<?xml version="1.0" encoding="utf-8"?>
<mujoco model="fanuc_lrmate_jaw">
    <compiler angle="radian" meshdir="robot_mesh/" coordinate="local" settotalmass="1"/>
    <option timestep="0.01" gravity="0 0 -10" noslip_iterations="200" iterations="200" integrator="RK4"/>
      <option>
    <!-- <flag multiccd="enable"/> -->
  </option>
    <!-- option refer to: http://www.mujoco.org/forum/index.php?threads/default-simulation-parameters-do-not-facilitate-simple-grips.2198/ -->
    <!-- impratio="5" -->
    <size nconmax="100" njmax="500"/>

    <!-- <extension>
        <plugin plugin="mujoco.sdf.torus">
        <instance name="torus">
            <config key="radius1" value="0.15"/>
            <config key="radius2" value="0.05"/>
        </instance>
        </plugin>
        <plugin plugin="mujoco.sdf.sdflib">
        <instance name="sdf">
            <config key="aabb" value="0.01"/>
        </instance>
        </plugin>
        <plugin plugin="mujoco.sdf.bowl">
        <instance name="bowl">
            <config key="height" value="0.025"/>
            <config key="radius" value="0.05"/>
            <config key="thickness" value="0.01"/>
        </instance>
        </plugin>
    </extension> -->

    <default>
        <!-- <geom contype='1' conaffinity='1' condim='4'  margin="0" solref=".02 1" solimp=".8 .9 .001" /> -->
        <joint armature="0.04" damping="1" limited="true" />
        <geom friction="0.2 .005 .0001" conaffinity="1" condim="4" contype="1" margin="0" solref=".02 1" solimp=".8 .9 .001"/>
        
    </default>

    <actuator>
        <motor ctrllimited="true" ctrlrange="-5.0 5.0" gear="1.0" joint="joint1" name="act1"/>
        <motor ctrllimited="true" ctrlrange="-5.0 5.0" gear="1.0" joint="joint2" name="act2"/>
        <motor ctrllimited="true" ctrlrange="-5.0 5.0" gear="1.0" joint="joint3" name="act3"/>
        <motor ctrllimited="true" ctrlrange="-5.0 5.0" gear="1.0" joint="joint4" name="act4"/>
        <motor ctrllimited="true" ctrlrange="-5.0 5.0" gear="1.0" joint="joint5" name="act5"/>
        <motor ctrllimited="true" ctrlrange="-5.0 5.0" gear="1.0" joint="joint6" name="act6"/>

        <!-- <position ctrllimited="true" ctrlrange="0 0.0435" joint="jointf1" kp="1" name="actf1"/>
        <position ctrllimited="true" ctrlrange="0 0.0435" joint="jointf2" kp="1" name="actf2"/> -->
        <adhesion name="adhere_winch1" body="suction_cup" ctrlrange="0 10" gain="10"/>
        <!-- <adhesion name="adhere_winch2" body="finger2" ctrlrange="0 .05" gain="1"/> -->
    </actuator>

    <asset>
        <mesh file="Base.STL" name="base" scale="0.001 0.001 0.001"></mesh>
        <mesh file="Link1.STL" name="link1" scale="0.001 0.001 0.001"></mesh>
        <mesh file="Link2.STL" name="link2" scale="0.001 0.001 0.001"></mesh>
        <mesh file="Link3.STL" name="link3" scale="0.001 0.001 0.001"></mesh>
        <mesh file="Link4.STL" name="link4" scale="0.001 0.001 0.001"></mesh>
        <mesh file="Link5.STL" name="link5" scale="0.001 0.001 0.001"></mesh>
        <mesh file="Link6.STL" name="link6" scale="0.001 0.001 0.001"></mesh>
        <mesh file="Sensor.STL" name="sensor" scale="0.001 0.001 0.001"></mesh>
        <mesh file="Palm.STL" name="palm" scale="0.001 0.001 0.001"></mesh>
        <mesh file="Finger1.STL" name="finger1" scale="0.001 0.001 0.001"></mesh>
        <mesh file="Finger2.STL" name="finger2" scale="0.001 0.001 0.001"></mesh>
        <mesh name="peg" file="peg_square_399.stl" scale="0.0095 0.0095 0.01"/>
        <mesh name="hole" file="hole_square_400.stl" scale="0.01 0.01 0.01"/>
        <!-- <mesh name="mug" file="Mug.stl" scale="0.001 0.001 0.001">
            <plugin instance="sdf"/>
        </mesh>
        <mesh name="cup" file="Cup.stl" scale="0.001 0.001 0.001">
            <plugin instance="sdf"/>
        </mesh>
        <mesh name="plate" file="Plate.obj" scale="1 1 1">
            <plugin instance="sdf"/>
        </mesh>
        <mesh name="bowl">
        <plugin instance="bowl"/>
        </mesh>
        <mesh name="box_base" file="box_bottom_remesh.stl" scale="0.002 0.002 0.002">
            <plugin instance="sdf"/>
        </mesh>
        <mesh name="box_base2" file="box_bottom_remesh.stl" scale="0.0012 0.0012 0.0012">
            <plugin instance="sdf"/>
        </mesh> -->

        <texture name="skybox" type="skybox" builtin="gradient" rgb1=".4 .6 .8" rgb2="0 0 0" width="1024" height="1024" mark="random" markrgb="1 1 1"/>
        <texture name="texplane" type="2d" builtin="checker" rgb1=".2 .3 .4" rgb2=".1 0.15 0.2" width="512" height="512" mark="cross" markrgb=".8 .8 .8"/>
        <material name="matplane" reflectance="0.3" texture="texplane" texrepeat="1 1" texuniform="true"/>
    </asset>

    <worldbody>
        <light directional="true" diffuse=".8 .8 .8" specular="0.1 0.1 0.1" pos="0 0 2.5" dir="0 0 -1" castshadow="false"/>
        <geom name="ground" type="plane" size="7 7 1" pos="0 0 0" quat="1 0 0 0" material="matplane" condim="1"/>
        <body name="base">
	        <!-- <inertial diaginertia="0 0 0" mass="0" pos="0 0 0" quat="1 0 0 0"/> -->
            <geom type="mesh" mesh="base" name="base" pos="0 0 0.33" rgba="0.5 0.5 0.5 1"></geom>
	        <body name="link1">
	            <inertial diaginertia="0.0233 0.0194 0.0139" mass="2.3984" pos="0.0186 0.0034 -0.0771" quat="0.7071 -0.7071 0 0"></inertial>
		        <joint axis="0 0 1" name="joint1" range="-3.1416 3.1416" type="hinge"/>
                <geom type="mesh" mesh="link1" name="link1" pos="0.05 0.0 0.33" quat="0.7071 -0.7071 0 0" rgba="1 1 0 1"></geom>
		        <body name="link2">
	                <inertial diaginertia="0.0329 0.2070 0.1884" mass="7.8019" pos="-0.0071 -0.1326 0.0248" quat="0 0.7071 -0.7071 0"></inertial>
		            <joint axis="0 1 0" pos="0.05 0.0 0.33" name="joint2" range="-2.129 2.129" type="hinge"/>
                    <geom type="mesh" mesh="link2" name="link2" pos="0.05 0.0 0.77" euler="1.57 0 1.57" rgba="1 1 0 1"></geom>
                    <body name="link3">
		                <inertial diaginertia="0.0081 0.0069 0.0080" mass="2.9847" pos="0.0058 -0.0059 -0.0207" quat="0 0.7071 -0.7071 0"></inertial>
                        <joint axis="0 -1 0" pos="0.05 0.0 0.77" name="joint3" range="-3.1416 3.1416" type="hinge"/>
                        <geom type="mesh" mesh="link3" name="link3" pos="0.05 0.0 0.805" euler="1.57 -1.57 1.57" rgba="1 1 0 1"></geom>
                        <body name="link4">
                            <inertial diaginertia="0.0529 0.0057 0.0532" mass="4.1442" pos="-0.0002 0.0028 -0.2061" quat="0.7071 0.7071 0 0"></inertial>
                            <joint axis="-1 0 0" pos="0.47 0.0 0.805" name="joint4" range="-3.1416 3.1416" type="hinge"/>
                            <geom type="mesh" mesh="link4" name="link4" pos="0.47 0.0 0.805" euler="1.57 0 1.57" rgba="1 1 0 1"></geom>
                            <body name="link5">
                                <inertial diaginertia="0.0025 0.0024 0.0012" mass="1.7004" pos="0.0000 -0.0274 -0.0044" quat="0.7071 -0.7071 0 0"></inertial>
                                <joint axis="0 -1 0" pos="0.47 0.0 0.805" name="joint5" range="-2.182 2.182" type="hinge"/>
                                <geom type="mesh" mesh="link5" name="link5" pos="0.47 0.0 0.805" euler="1.57 -1.57 1.57" rgba="1 1 0 1"></geom>
                                <body name="link6">
                                    <inertial diaginertia="0.00003 0.00003 0.00005" mass="1.1700" pos="0.0 0.0 -0.08" quat="0 1 0 0"></inertial>
                                    <joint axis="1 0 0" pos="0.55 0.0 0.805" name="joint6" range="-3.1416 3.1416" type="hinge"/>
                                    <geom type="mesh" mesh="link6" name="link6" pos="0.55 0.0 0.805" euler="1.57 1.57 1.57" rgba="0 0 0 1"></geom>
                                    <site name="vertex1" pos="0.55 0.0 0.805" euler="1.57 1.57 1.57" type="sphere" size="0.005" rgba="0.6 0.8 0.1 1"/>
                                    <body name="sensor">
            				            <geom type="mesh" mesh="sensor" name="sensor" pos="0.62 -0.0325 0.7725" euler="0 -1.57 0" rgba="0.7 0.7 0.7 1"></geom>
                                        <body name="suction_cup">
                                            <geom type="box" name="suction_bar" size="0.01 0.04 0.01" pos="0.65 0.0 0.805" euler="0 0 1.57" rgba="0.7 0.7 0.7 1"></geom>
                                            <geom type="cylinder" name="suction_cup" size="0.05 0.01" pos="0.70 0.0 0.805" euler="0 1.57 0" rgba="0.7 0.7 0.7 1"></geom>
                                        </body>
				                    </body>
				                </body>
			                </body>
			            </body>
		            </body>
                </body>
            </body>
        </body>

        <!-- <body euler="0 0 0" pos="0.5 0 0.05">
            <geom type="sdf" name="mug1" mesh="mug" >
            <plugin instance="sdf"/>
            </geom>
            <freejoint name="mug1"/>
        </body>

        <body euler="0 0 0" pos="0.5 0.1 0.075">
            <geom type="sdf" name="cup1" mesh="cup" >
            <plugin instance="sdf"/>
            </geom>
            <freejoint name="cup1"/>
        </body> -->

        <!-- <body euler="0 0 0" pos="0.5 1 0.075">
            <geom type="sdf" name="plate1" mesh="plate" >
            <plugin instance="sdf"/>
            </geom>
            <freejoint name="plate1"/>
        </body> -->
        <!-- <body euler="0 -0 0" pos="0.6 -0.1 0.1">
        <geom type="sdf" name="bowl" mesh="bowl" rgba=".2 .8 .8 1">
            <plugin instance="bowl"/>
        </geom>
        <freejoint name="bowl"/> -->
        <!-- </body> -->
        <body name="table" euler="0 0 0" pos="0.6 0 0.02">
            <geom type="box" size="0.3 0.4 0.02" name="table" rgba="0.5 0.5 0.5 1"/>
        </body>
        <!-- <body euler="0 0 0" pos="0.5 -0.0 0.2">
            <geom type="sdf" name="box" mesh="box_base" density="100">
            <plugin instance="sdf"/>
            </geom>
            <freejoint name="box"/>
        </body> -->

        <body name="shelf1" pos="0.5 0 0.2">
            <geom type="box" size="0.1 0.21 0.005" name="shelf1_top" pos="0 0 0.025" rgba="0.5 0.5 0.5 1"/>
            <geom type="box" size="0.1 0.005 0.05" name="shelf1_side1" pos="0 -0.2 -0.025" rgba="0.5 0.5 0.5 1"/>
            <geom type="box" size="0.1 0.005 0.05" name="shelf1_side2" pos="0 0.2 -0.025" rgba="0.5 0.5 0.5 1"/>
            <freejoint name="shelf1"/>
        </body>

        <body name="shelf2" pos="0.5 0 0.16">
            <geom type="box" size="0.1 0.16 0.005" name="shelf2_top" pos="0 0 0.02" rgba="0.5 0.5 0.5 1"/>
            <geom type="box" size="0.1 0.005 0.04" name="shelf2_side1" pos="0 -0.16 -0.02" rgba="0.5 0.5 0.5 1"/>
            <geom type="box" size="0.1 0.005 0.04" name="shelf2_side2" pos="0 0.16 -0.02" rgba="0.5 0.5 0.5 1"/>
            <freejoint name="shelf2"/>
        </body>

        <body name="shelf3" pos="0.5 0 0.1">
            <geom type="box" size="0.1 0.1 0.005" name="shelf3_top" pos="0 -0.0 0.0125" rgba="0.5 0.5 0.5 1"/>
            <geom type="box" size="0.1 0.005 0.025" name="shelf3_side1" pos="0 -0.1 -0.0125" rgba="0.5 0.5 0.5 1"/>
            <geom type="box" size="0.1 0.005 0.025" name="shelf3_side2" pos="0 0.1 -0.0125" rgba="0.5 0.5 0.5 1"/>
            <freejoint name="shelf3"/>
        </body>

        <body name="item" pos="0.5 0 0.07">
            <geom type="box" size="0.02 0.02 0.02" name="item" rgba="1 0. 0. 1"/>
            <freejoint name="item"/>
        </body>

        <!-- <body euler="0 0 0" pos="0.5 -0.0 0.2">
            <geom type="sdf" name="box2" mesh="box_base2" density="100">
            <plugin instance="sdf"/>
            </geom>
            <freejoint name="box2"/>
        </body> -->

        <!-- <body name="hole" pos="0 0 0.11">
            <geom name='hole_base_geom' type="box" size="0.075 0.075 0.015" pos="0.5 0 -0.025" rgba="0.1 0.074 0.02 1" friction="0.3"/> -->
            <!-- <geom name='hole_geom_1' type="mesh" pos="0.5 0 0" mesh="hole" rgba = "0.1 0.074 0.02 1" contype="1" conaffinity="1" friction="0.3"/>
            <geom name='hole_geom_2' type="mesh" pos="0.5 0 0" quat = "0 0 1 0" mesh="hole" rgba = "0.1 0.074 0.02 1" contype="1" conaffinity="1" friction="0.3"/>
            <geom name='hole_geom_3' type="mesh" pos="0.5 0 0" quat = "0 1 1 0" mesh="hole" rgba = "0.1 0.074 0.02 1" contype="1" conaffinity="1" friction="0.3"/>
            <geom name='hole_geom_4' type="mesh" pos="0.5 0 0" quat = "0 -1 1 0" mesh="hole" rgba = "0.1 0.074 0.02 1" contype="1" conaffinity="1" friction="0.3"/> -->

        <!-- </body> -->

    </worldbody>

    <sensor>
        <force name="force_ee" site="vertex1"/>
        <torque name="torque_ee" site="vertex1"/>
    </sensor>
    
</mujoco>

<!-- <body name="palm">
                                            <geom type="mesh" mesh="palm" name="palm" pos="0.703 -0.07 0.7875" euler="0 0 1.57" rgba="0.7 0.7 0.7 1"></geom>
                                            <body name="finger1">
            				                    <!-- <geom type="mesh" mesh="finger1" name="finger1" solimp="0.99 0.99 0.01" solref="0.01 1" pos="0.700 -0.047 0.7875" euler="1.57 0 0" rgba="0.7 0.7 0.7 1"></geom> -->
                                                <geom type="box" size="0.01 0.02 0.05" name="finger1" solimp="0.99 0.99 0.01" solref="0.01 1" pos="0.750 -0.047 0.8055" euler="0 1.57 0" rgba="0.7 0.7 0.7 1"></geom>
                                                <joint axis="0 1 0" pos="0 0 0" name="jointf1" damping="3" range="0 0.0435" type="slide"/>
                                            </body>
					                        <body name="finger2">
            				                    <!-- <geom type="mesh" mesh="finger2" name="finger2" solimp="0.99 0.99 0.01" solref="0.01 1" pos="0.700 0.047 0.7875" euler="1.57 0 0" rgba="0.7 0.7 0.7 1"></geom> -->
<!--                                                <geom name="peg_geom" pos="0.55 0.0 0.905" type="mesh" mesh="peg" contype="1" conaffinity="1" rgba="1 0 0 1"/>-->
                                                <geom type="box" size="0.01 0.02 0.05" name="finger2" solimp="0.99 0.99 0.01" solref="0.01 1" pos="0.750 0.047 0.8055" euler="0 1.57 0" rgba="0.7 0.7 0.7 1"></geom>
                                                <joint axis="0 -1 0" pos="0 0 0" name="jointf2" damping="3" range="0 0.0435" type="slide"/>
				                            </body>
				                        </body> -->